<robot
  name="redhawk">
  <link name="world"/>
  <link
    name="base_link">
    <inertial>
      <origin
        xyz="-0.242696775784451 -0.0630818724626695 0.123350574572946"
        rpy="0 0 0" />
      <mass
        value="190.807213510781" />
      <inertia
        ixx="17.148394236804"
        ixy="-0.0193627735618233"
        ixz="0.236569669331495"
        iyy="40.1810883491995"
        iyz="-0.0155922676417971"
        izz="53.7814456090568" />
    </inertial>
    <visual>
      <origin
        xyz="0 0 0"
        rpy="0 0 0" />
      <geometry>
        <mesh
          filename="package://redhawk_moveit/meshes/base_link.STL" />
      </geometry>
      <material
        name="">
        <color
          rgba="0.792156862745098 0.819607843137255 0.933333333333333 1" />
      </material>
    </visual>
    <collision>
      <origin
        xyz="0 0 0"
        rpy="0 0 0" />
      <geometry>
        <mesh
          filename="package://redhawk_moveit/meshes/base_link.STL" />
      </geometry>
    </collision>
  </link>

  <joint name="fixed" type="fixed">
    <parent link="world"/>
    <child link="base_link"/>
  </joint>

  <link
    name="link1">
    <inertial>
      <origin
        xyz="-3.46944695195361E-18 8.130935723491E-05 -0.0381604608040978"
        rpy="0 0 0" />
      <mass
        value="0.784004998006185" />
      <inertia
        ixx="0.00105221140887869"
        ixy="-8.10783458797717E-20"
        ixz="-8.96418691774108E-20"
        iyy="0.00105532277356618"
        iyz="-3.85419139979644E-09"
        izz="0.001349932660026" />
    </inertial>
    <visual>
      <origin
        xyz="0 0 0"
        rpy="0 0 0" />
      <geometry>
        <mesh
          filename="package://redhawk_moveit/meshes/link1.STL" />
      </geometry>
      <material
        name="">
        <color
          rgba="0.792156862745098 0.819607843137255 0.933333333333333 1" />
      </material>
    </visual>
    <collision>
      <origin
        xyz="0 0 0"
        rpy="0 0 0" />
      <geometry>
        <mesh
          filename="package://redhawk_moveit/meshes/link1.STL" />
      </geometry>
    </collision>
  </link>

  <joint
    name="joint1"
    type="revolute">
    <origin
      xyz="0 0 0.396113"
      rpy="3.14159265358979 -9.08740001431347E-47 3.14159265358979" />
    <parent
      link="base_link" />
    <child
      link="link1" />
    <axis
      xyz="0 0 1" />
    <limit lower="-3.49" upper="3.49" effort="1000" velocity="0.5"/>
  </joint>

  <link
    name="link2">
    <inertial>
      <origin
        xyz="-1.94289029309402E-16 0.155455741173879 -0.124534060356386"
        rpy="0 0 0" />
      <mass
        value="3.74499800319706" />
      <inertia
        ixx="0.110285859722925"
        ixy="1.20796220160134E-16"
        ixz="-1.76603380418917E-17"
        iyy="0.0105248162125277"
        iyz="0.015057589986012"
        izz="0.105565156784639" />
    </inertial>
    <visual>
      <origin
        xyz="0 0 0"
        rpy="0 0 0" />
      <geometry>
        <mesh
          filename="package://redhawk_moveit/meshes/link2.STL" />
      </geometry>
      <material
        name="">
        <color
          rgba="0.792156862745098 0.819607843137255 0.933333333333333 1" />
      </material>
    </visual>
    <collision>
      <origin
        xyz="0 0 0"
        rpy="0 0 0" />
      <geometry>
        <mesh
          filename="package://redhawk_moveit/meshes/link2.STL" />
      </geometry>
    </collision>
  </link>

  <joint
    name="joint2"
    type="revolute">
    <origin
      xyz="0 -0.04826 -0.0381"
      rpy="-1.5707963267949 -1.17961196366423E-15 0" />
    <parent
      link="link1" />
    <child
      link="link2" />
    <axis
      xyz="0 0 1" />
    <limit lower="-1.57" upper="1.57" effort="1000" velocity="0.5"/>
  </joint>

  <link
    name="link3">
    <inertial>
      <origin
        xyz="-1.3878E-17 -0.0027083 -0.062451"
        rpy="0 0 0" />
      <mass
        value="1.185" />
      <inertia
        ixx="0.0023346"
        ixy="-2.2057E-19"
        ixz="2.639E-19"
        iyy="0.0022189"
        iyz="-3.3525E-05"
        izz="0.0019087" />
    </inertial>
    <visual>
      <origin
        xyz="0 0 0"
        rpy="0 0 0" />
      <geometry>
        <mesh
          filename="package://redhawk_moveit/meshes/link3.STL" />
      </geometry>
      <material
        name="">
        <color
          rgba="0.79216 0.81961 0.93333 1" />
      </material>
    </visual>
    <collision>
      <origin
        xyz="0 0 0"
        rpy="0 0 0" />
      <geometry>
        <mesh
          filename="package://redhawk_moveit/meshes/link3.STL" />
      </geometry>
    </collision>
  </link>

  <joint
    name="joint3"
    type="revolute">
    <origin
      xyz="0 0.4445 -0.126238"
      rpy="3.14159265358979 6.93889390390723E-17 0" />
    <parent
      link="link2" />
    <child
      link="link3" />
    <axis
      xyz="0 0 -1" />
	<limit lower="-3.14" upper="3.14" effort="1000" velocity="0.5"/>
  </joint>

  <link
    name="link4">
    <inertial>
      <origin
        xyz="-2.42861286636753E-17 0.0003313284114487 -0.15427332018414"
        rpy="0 0 0" />
      <mass
        value="2.87457615664221" />
      <inertia
        ixx="0.0234190289824234"
        ixy="1.41997682393559E-19"
        ixz="5.2151597957512E-18"
        iyy="0.0234055865436832"
        iyz="0.000128740619244794"
        izz="0.00446702614178736" />
    </inertial>
    <visual>
      <origin
        xyz="0 0 0"
        rpy="0 0 0" />
      <geometry>
        <mesh
          filename="package://redhawk_moveit/meshes/link4.STL" />
      </geometry>
      <material
        name="">
        <color
          rgba="0.792156862745098 0.819607843137255 0.933333333333333 1" />
      </material>
    </visual>
    <collision>
      <origin
        xyz="0 0 0"
        rpy="0 0 0" />
      <geometry>
        <mesh
          filename="package://redhawk_moveit/meshes/link4.STL" />
      </geometry>
    </collision>
  </link>

  <joint
    name="joint4"
    type="continuous">
    <origin
      xyz="0 -0.0546099999999999 -0.072898"
      rpy="-1.5707963267949 6.93889390390723E-17 -6.93889390390722E-16" />
    <parent
      link="link3" />
    <child
      link="link4" />
    <axis
      xyz="0 0 1" />
    <limit effort="1000" velocity="0.85"/>
  </joint>

  <link
    name="link5">
    <inertial>
      <origin
        xyz="0 -0.00280217821796258 -0.0743410955268955"
        rpy="0 0 0" />
      <mass
        value="0.997048418279697" />
      <inertia
        ixx="0.00207561674496563"
        ixy="3.01356436576703E-20"
        ixz="2.52091925823776E-19"
        iyy="0.00200100288765086"
        iyz="-5.15339131425933E-05"
        izz="0.00120168883221164" />
    </inertial>
    <visual>
      <origin
        xyz="0 0 0"
        rpy="0 0 0" />
      <geometry>
        <mesh
          filename="package://redhawk_moveit/meshes/link5.STL" />
      </geometry>
      <material
        name="">
        <color
          rgba="0.792156862745098 0.819607843137255 0.933333333333333 1" />
      </material>
    </visual>
    <collision>
      <origin
        xyz="0 0 0"
        rpy="0 0 0" />
      <geometry>
        <mesh
          filename="package://redhawk_moveit/meshes/link5.STL" />
      </geometry>
    </collision>
  </link>

  <joint
    name="joint5"
    type="revolute">
    <origin
      xyz="0 0.04826 -0.28194"
      rpy="1.5708 -6.9389E-16 -6.9389E-17" />
    <parent
      link="link4" />
    <child
      link="link5" />
    <axis
      xyz="0 0 -1" />
    <limit lower="-3.14" upper="3.14" effort="1000" velocity="0.85"/>
  </joint>

  <link
    name="link6">
    <inertial>
      <origin
        xyz="-1.04083408558608E-17 0 0.198830566523384"
        rpy="0 0 0" />
      <mass
        value="4.79143893371128" />
      <inertia
        ixx="0.07937014489573"
        ixy="-8.49903797787081E-19"
        ixz="2.30708915172358E-18"
        iyy="0.07937014489573"
        iyz="2.37951170760947E-19"
        izz="0.00877304530397157" />
    </inertial>
    <visual>
      <origin
        xyz="0 0 0"
        rpy="0 0 0" />
      <geometry>
        <mesh
          filename="package://redhawk_moveit/meshes/link6.STL" />
      </geometry>
      <material
        name="">
        <color
          rgba="0.792156862745098 0.819607843137255 0.933333333333333 1" />
      </material>
    </visual>
    <collision>
      <origin
        xyz="0 0 0"
        rpy="0 0 0" />
      <geometry>
        <mesh
          filename="package://redhawk_moveit/meshes/link6.STL" />
      </geometry>
    </collision>
  </link>

  <joint
    name="joint6"
    type="continuous">
    <origin
      xyz="0 -0.484165 -0.0927862"
      rpy="-1.5707963267949 6.93889390390723E-17 -9.71445146547011E-16" />
    <parent
      link="link5" />
    <child
      link="link6" />
    <axis
      xyz="0 0 1" />
    <limit effort="1000" velocity="0.85"/>
  </joint>

  <transmission name="trans1">
    <type>transmission_interface/SimpleTransmission</type>
    <actuator name="act1">
      <mechanicalReduction>1</mechanicalReduction>
      <hardwareInterface>PositionJointInterface</hardwareInterface>
    </actuator>
    <joint name="joint1">
      <hardwareInterface>hardware_interface/PositionJointInterface</hardwareInterface>
    </joint>
  </transmission>

  <transmission name="trans2">
    <type>transmission_interface/SimpleTransmission</type>
    <actuator name="act2">
      <mechanicalReduction>1</mechanicalReduction>
      <hardwareInterface>PositionJointInterface</hardwareInterface>
    </actuator>
    <joint name="joint2">
      <hardwareInterface>hardware_interface/PositionJointInterface</hardwareInterface>
    </joint>
  </transmission>

  <transmission name="trans3">
    <type>transmission_interface/SimpleTransmission</type>
    <actuator name="act3">
      <mechanicalReduction>1</mechanicalReduction>
      <hardwareInterface>PositionJointInterface</hardwareInterface>
    </actuator>
    <joint name="joint3">
      <hardwareInterface>hardware_interface/PositionJointInterface</hardwareInterface>
    </joint>
  </transmission>

  <transmission name="trans4">
    <type>transmission_interface/SimpleTransmission</type>
    <actuator name="act4">
      <mechanicalReduction>1</mechanicalReduction>
      <hardwareInterface>PositionJointInterface</hardwareInterface>
    </actuator>
    <joint name="joint4">
      <hardwareInterface>hardware_interface/PositionJointInterface</hardwareInterface>
    </joint>
  </transmission>

  <transmission name="trans5">
    <type>transmission_interface/SimpleTransmission</type>
    <actuator name="act5">
      <mechanicalReduction>1</mechanicalReduction>
      <hardwareInterface>PositionJointInterface</hardwareInterface>
    </actuator>
    <joint name="joint5">
      <hardwareInterface>hardware_interface/PositionJointInterface</hardwareInterface>
    </joint>
  </transmission>

  <transmission name="trans6">
    <type>transmission_interface/SimpleTransmission</type>
    <actuator name="act6">
      <mechanicalReduction>1</mechanicalReduction>
      <hardwareInterface>PositionJointInterface</hardwareInterface>
    </actuator>
    <joint name="joint6">
      <hardwareInterface>hardware_interface/PositionJointInterface</hardwareInterface>
    </joint>
  </transmission>

  <gazebo>
    <plugin name="gazebo_ros_control" filename="libgazebo_ros_control.so">
      <robotNamespace>/redhawk</robotNamespace>
    </plugin>
    <plugin name="joint_state_publisher"
	filename="libgazebo_ros_joint_state_publisher.so">
      <jointName>joint1,joint2,joint3,joint4,joint5,joint6</jointName>
    </plugin>
  </gazebo>

</robot>
